2023-10-30 14:22:29,600 INFO    StreamThr :119523 [internal.py:wandb_internal():86] W&B internal server running at pid: 119523, started at: 2023-10-30 14:22:29.600043
2023-10-30 14:22:29,604 DEBUG   HandlerThread:119523 [handler.py:handle_request():146] handle_request: status
2023-10-30 14:22:29,606 INFO    WriterThread:119523 [datastore.py:open_for_write():85] open: /home/henry/Documents/BCI/wandb/run-20231030_142229-srlxrj8b/run-srlxrj8b.wandb
2023-10-30 14:22:29,607 DEBUG   SenderThread:119523 [sender.py:send():380] send: header
2023-10-30 14:22:29,608 DEBUG   SenderThread:119523 [sender.py:send():380] send: run
2023-10-30 14:22:29,792 ERROR   SenderThread:119523 [internal_api.py:execute():369] 401 response executing GraphQL.
2023-10-30 14:22:29,792 ERROR   SenderThread:119523 [internal_api.py:execute():370] {"errors":[{"message":"user is not logged in","path":["upsertBucket"],"extensions":{"code":"PERMISSION_ERROR"}}],"data":{"upsertBucket":null}}
2023-10-30 14:22:29,793 ERROR   SenderThread:119523 [sender.py:send_run():977] The API key you provided is either invalid or missing.  If the `WANDB_API_KEY` environment variable is set, make sure it is correct. Otherwise, to resolve this issue, you may try running the 'wandb login --relogin' command. If you are using a local server, make sure that you're using the correct hostname. If you're not sure, you can try logging in again using the 'wandb login --relogin --host [hostname]' command.(Error 401: Unauthorized)
Traceback (most recent call last):
  File "/home/henry/.local/lib/python3.11/site-packages/wandb/sdk/lib/retry.py", line 131, in __call__
    result = self._call_fn(*args, **kwargs)
             ^^^^^^^^^^^^^^^^^^^^^^^^^^^^^^
  File "/home/henry/.local/lib/python3.11/site-packages/wandb/sdk/internal/internal_api.py", line 366, in execute
    return self.client.execute(*args, **kwargs)  # type: ignore
           ^^^^^^^^^^^^^^^^^^^^^^^^^^^^^^^^^^^^
  File "/home/henry/.local/lib/python3.11/site-packages/wandb/vendor/gql-0.2.0/wandb_gql/client.py", line 52, in execute
    result = self._get_result(document, *args, **kwargs)
             ^^^^^^^^^^^^^^^^^^^^^^^^^^^^^^^^^^^^^^^^^^^
  File "/home/henry/.local/lib/python3.11/site-packages/wandb/vendor/gql-0.2.0/wandb_gql/client.py", line 60, in _get_result
    return self.transport.execute(document, *args, **kwargs)
           ^^^^^^^^^^^^^^^^^^^^^^^^^^^^^^^^^^^^^^^^^^^^^^^^^
  File "/home/henry/.local/lib/python3.11/site-packages/wandb/sdk/lib/gql_request.py", line 59, in execute
    request.raise_for_status()
  File "/usr/lib/python3.11/site-packages/requests/models.py", line 1021, in raise_for_status
    raise HTTPError(http_error_msg, response=self)
requests.exceptions.HTTPError: 401 Client Error: Unauthorized for url: https://api.wandb.ai/graphql

During handling of the above exception, another exception occurred:

Traceback (most recent call last):
  File "/home/henry/.local/lib/python3.11/site-packages/wandb/sdk/internal/sender.py", line 975, in send_run
    self._init_run(run, config_value_dict)
  File "/home/henry/.local/lib/python3.11/site-packages/wandb/sdk/internal/sender.py", line 1013, in _init_run
    server_run, inserted, server_messages = self._api.upsert_run(
                                            ^^^^^^^^^^^^^^^^^^^^^
  File "/home/henry/.local/lib/python3.11/site-packages/wandb/apis/normalize.py", line 73, in wrapper
    raise err
  File "/home/henry/.local/lib/python3.11/site-packages/wandb/apis/normalize.py", line 41, in wrapper
    return func(*args, **kwargs)
           ^^^^^^^^^^^^^^^^^^^^^
  File "/home/henry/.local/lib/python3.11/site-packages/wandb/sdk/internal/internal_api.py", line 2007, in upsert_run
    response = self.gql(
               ^^^^^^^^^
  File "/home/henry/.local/lib/python3.11/site-packages/wandb/sdk/internal/internal_api.py", line 338, in gql
    ret = self._retry_gql(
          ^^^^^^^^^^^^^^^^
  File "/home/henry/.local/lib/python3.11/site-packages/wandb/sdk/lib/retry.py", line 147, in __call__
    retry_timedelta_triggered = check_retry_fn(e)
                                ^^^^^^^^^^^^^^^^^
  File "/home/henry/.local/lib/python3.11/site-packages/wandb/util.py", line 964, in check_retry_fn
    return fallback_retry_fn(e)
           ^^^^^^^^^^^^^^^^^^^^
  File "/home/henry/.local/lib/python3.11/site-packages/wandb/util.py", line 895, in no_retry_auth
    raise AuthenticationError(
wandb.errors.AuthenticationError: The API key you provided is either invalid or missing.  If the `WANDB_API_KEY` environment variable is set, make sure it is correct. Otherwise, to resolve this issue, you may try running the 'wandb login --relogin' command. If you are using a local server, make sure that you're using the correct hostname. If you're not sure, you can try logging in again using the 'wandb login --relogin --host [hostname]' command.(Error 401: Unauthorized)
2023-10-30 14:22:30,247 DEBUG   HandlerThread:119523 [handler.py:handle_request():146] handle_request: shutdown
2023-10-30 14:22:30,247 INFO    HandlerThread:119523 [handler.py:finish():866] shutting down handler
2023-10-30 14:22:30,608 INFO    WriterThread:119523 [datastore.py:close():294] close: /home/henry/Documents/BCI/wandb/run-20231030_142229-srlxrj8b/run-srlxrj8b.wandb
2023-10-30 14:22:30,803 INFO    SenderThread:119523 [sender.py:finish():1534] shutting down sender
